Workbook

Sheet Explanation and FAQ
A1: Country Risk Premiums
A2: To estimate the equity risk premium for a country, I start with a mature market premium and add an additional country risk premium, based upon the risk of the country in question.
A3: Use the look up table in the next worksheet, to look up the statistics for an individual country or region.
A5: Step 1: Estimating mature market risk premium
A6: To estimate the mature market risk premium, I start with the implied equity risk premium for the S&P 500. To see the latest estimate for this number, go to my website and you can download the excel spreadsheet containing the implied premium
A7: Link to site: | B7: http://www.damodaran.com
A8: Historical monthly ERP: | B8: https://pages.stern.nyu.edu/~adamodar/pc/implprem/ERPbymonth.xls
A9: Until the January 2025 update, I used the S&P's equity risk premium as the mature market premium, drawing on the Moody's Aaa rating for the United States.
A10: On May 16, 2025, Moody's downgraded the US from Aaa to Aa1. To get the mature market premium, I now subtract the US's country risk premium (based on its rating and the relative equity market volatility) from the S&P's eRP
A11: Mature market premium = ERP for the S&P 500 minus (Default spread for US sovereign rating × Relative Equity Volatility)
A12: In January 2026, for example, when the implied ERP for the S&P 500 was 4.59% (over the adjusted dollar riskfree rate), the US had a rating of Aa1 and the default spread for that rating was 0.23% and the relative equity market volatility was 1.52
A13: Mature market premium = 4.61% - (0.23% × 1.52) = 4.23%
A15: Step 2: Estimate the default spread for the country in question. I offer two choices, one based upon the local currency sovereign rating for the country from Moody's and the other is the CDS spread for the country (if one exists)
A16: Moody's ratings: | B16: http://www.moodys.com | D16: (You will have to register, but it is free. Look under sovereign ratings)
A17: Ratings to spreads: | B17: Based upon my estimates of typical spreads for each ratings class. I compute these by averaging CDS spreads and sovereign US$ bond spreads by ratings class, at the start of every year.
A18: CDS spreads: | B18: Bloomberg
A19: If you cannot find a country on this list, it is because that country does not have a sovereign rating or a sovereign CDS spread. Try the PRS worksheet in this spreadsheet for an alternate estimate.
A21: Step 3: Convert the default spread into a country risk premium
A22: With sovereign ratings default spreads, you have two choices:
A23: Choice 1: Use the default spread as the measure of the additional country risk premium. To make this choice, go into the ERP worksheet and set cell E5 to 1.00.
A24: Choice 2: Scale the default spread up to reflect the higher risk of equity in the market, relative to the default spread. I used the ratio of the S&P Emerging Market Equity Index std deviation to the iShares Emerging Market Bond Index standard deviation
A25: With CDS spreads, I compute the base number in two steps
A26: Substep 1: Since the base equity premium is for a mature market (assumed to be default free), I net out the CDS spread for Switzerland (the lowest sovereign CDS) from each country's CDS to get a net spread.
A27: Substep 2: I apply the scaling factor that you chose for the default spreads to this number to get a country risk premium. The default scaling is set at the my most recent year's estimate, but you can change it to 1, if you would
A28: prefer not to scale the default spread.
A30: Step 4: Compute a total equity risk premium
A31: Add the mature market premium from step 1 to the country risk premium from step 3 to get a total equity risk premium.
A33: Step 5: Compute regional averages and regional weighted averages
... A35: For the weighted averages, I use the World Bank GDP estimates from the most recent year.
I36: https://data.worldbank.org/indicator/NY.GDP.MKTP.CD
A37: If you are interested in a fuller explanation of these concepts, try these references:
A38: My paper on equity risk premiums:
A39: My paper on country risk premiums: | E39: https://papers.ssrn.com/sol3/papers.cfm?abstract_id=4398884
A40: Watch my lectures on country risk premiums: | E40: https://papers.ssrn.com/sol3/papers.cfm?abstract_id=4509578
E41: https://www.youtube.com/watch?v=aIRPvY2SQ94
E42: https://www.youtube.com/watch?v=D3IGn6tH03c

Sheet Summary of Most Recent Update
B1: Update Notes
A2: Mature Marlet Premium | B2: The starting point for the mature market premiums is the implied equity risk premium for the S&P 500. You can review the calcualtion in this spreadsheet. (https://pages.stern.nyu.edu/~adamodar/pc/implprem/ERPJan26.xlsx). I net out a riskfree rate in US dollars, which is the treasury bond rate adjusted for the default spread for the US, to get an equity risk premium for the US. I then back out the US default spread to get a mature market premium.
A3: US ERP | B3: ERP for US = Implled Expected Return on US stocks - (US 10-yr T.Bond - Default spread for US)
A4: Mature market ERP | B4: Mature market ERP = ERP for US - Default spread for US
A5: Sovereign Ratings | B5: The ratings (Moody's and S&P) have been updated to reflect the most recent ratings. (See Ratings Worksheet)
A6: Default Spreads | B6: The change in default spreads is computed by looking at percentage changes in sovereign CDS spreads over the period. (See Default Spreads for Ratings worksheet)
A7: Relative Equity Market Volatility | B7: The biggest change in this update is in this measure. For the last few years, I have used the coefficient of variation in emerging market bond yields and the standard deviation of returns in emerging market equities. In this iteration, I have replaced the former with the standard defiation in emerging market sovereign bond ETF returns, thus creating more consistency in the calcuatlions. While this change does not create a substantive shift in the numbers in this iteration, I think it is a more solid basis for computing this value in future ones.
A8: Bottom Line | B8: The combination of a lower base mature market premium and lower sovereign default spreads has led to lower equity risk premiums across the board, a climb down from historically high numbers at the start of the year.

Sheet Country Lookup
A1: To look up the equity risk premium for a country, use this worksheet
A2: Country | B2: Turkey | D2: If you cannot find a country on this list, it is because that country does not have a sovereign rating
D3: or a sovereign CDS spread. Try the PRS worksheet in this spreadsheet for an alternate estimate.
A4: Moody's sovereign rating | B4: =VLOOKUP(B2,'Ratings worksheet'!$A$2:$C$159,3, FALSE()) -> Ba3 | C4: Local currency
A5: S&P sovereign rating | B5: =VLOOKUP(B2,'Ratings worksheet'!$A$2:$C$159,2, FALSE()) -> BB- | C5: Local currency
A6: CDS spread | B6: =VLOOKUP(B2,'10-year CDS Spreads'!A2:D158,3, FALSE()) -> 0.0299
A7: Excess CDS spread (over Swiss CDS) | B7: =IF(B6="NA","NA",VLOOKUP(B2,'ERPs by country'!A9:I165,9,FALSE())/'ERPs by country'!E6) -> 0.0285
A9: Country Default Spread (based on rating) | B9: =VLOOKUP(B2,'ERPs by country'!A9:I165,4,FALSE()) -> 0.030563925
A10: Country Risk Premium (Rating) | B10: =VLOOKUP(B2,'ERPs by country'!A9:I165,6,FALSE()) -> 0.046560415
A11: Equity Risk Premium (Rating) | B11: =VLOOKUP(B2,'ERPs by country'!A9:I165,5,FALSE()) -> 0.088860415
A13: Country Risk Premium (CDS) | B13: =VLOOKUP(B2,'ERPs by country'!A9:I165,9,FALSE()) -> 0.043416277
A14: Equity Risk Premium (CDS) | B14: =VLOOKUP(B2,'ERPs by country'!A9:I165,8,FALSE()) -> 0.085716277
A16: To look up the equity risk premium for a region, use this worksheet
A17: Region | B17: Asia
A19: Country Risk Premium (simple average)) | B19: =VLOOKUP(B17,'Regional Simple Averages'!$A$5:$E$13,3,FALSE()) -> 0.048341934
A20: Total Equity Risk Premium (simple average) | B20: =VLOOKUP(B17,'Regional Simple Averages'!$A$5:$E$13,4,FALSE()) -> 0.090641934
A22: Country Risk Premium (GDP weighted) | B22: =VLOOKUP(B17,'Regional Weighted Averages'!A171:C179,3,FALSE()) -> 0.014923236
A23: Total Equity Risk Premium (GDP weighted) | B23: =VLOOKUP(B17,'Regional Weighted Averages'!A171:C179,2,FALSE()) -> 0.057223236
A25: To construct your own regional ERP, use the data on GDP and ERP for countries in the Regional Weighted Averages Worksheet
A27: For countries not on the list above, try this frontier market list
A28: Country | B28: Zimbabwe
A30: PRS Score | B30: =VLOOKUP(B28,'PRS Worksheet'!A162:E182,2,FALSE()) -> 58.5
A31: ERP based on PRS Score | B31: =VLOOKUP(B28,'PRS Worksheet'!A162:E182,5,FALSE()) -> 0.1588532

Sheet ERPs by country
A1: Country and Equity Risk Premiums
A2: Date of update: | B2: 44561 | C2: (Updated Feb 16 for sovereign ratings
A3: Enter the current risk premium for a mature equity market | E3: 0.0423 | F3: Implied ERP for S&P 500 with adjusted dollar riskfree rate (for US Aa1 rating
A4: Enter the current risk premium for the US = | E4: 0.0446 | F4: US equity risk premium computed using implied ERP approach
A5: Do you want to adjust the country default spread for the additional volatility of the equity market to get to a country premium? | E5: Yes
A6: If yes, enter the multiplier to use on the default spread (See worksheet for volatility numbers for selected emerging markets) | E6: ='Relative Equity Volatility'!D7 -> 1.5233781 | F6: See "Relative Equity Volatilty" worksheet
A8: Country | B8: Africa | C8: Moody's rating | D8: Rating-based Default Spread | E8: Total Equity Risk Premium | F8: Country Risk Premium | G8: Sovereign CDS, net of Swiss CDS | H8: Total Equity Risk Premium2 | I8: Country Risk Premium3 | J8: Has to be sorted in ascending order
A9: ='Sovereign Ratings (Moody''s,S&P)'!A2 -> Abu Dhabi | B9: =VLOOKUP(A9,'Regional lookup table'!$A$2:$B$162,2,FALSE()) -> Middle East | C9: =VLOOKUP(A9,'Sovereign Ratings (Moody''s,S&P)'!$A$2:$D$158,4,FALSE()) -> Aa2 | D9: =VLOOKUP(C9,$J$10:$K$32,2,FALSE())/10000 -> 0.0041950485 | E9: =$E$3+F9 -> 0.048690645 | F9: =IF($E$5="Yes",D9*$E$6,D9) -> 0.0063906452 | G9: =VLOOKUP(A9,'10-year CDS Spreads'!$A$2:$D$158,4,FALSE()) -> 0.0046 | H9: =IF(I9="NA","NA",$E$3+I9) -> 0.049307539 | I9: =IF(G9="NA","NA",G9*$E$6) -> 0.0070075394 | J9: Rating | K9: Default spread in basis points
A10: ='Sovereign Ratings (Moody''s,S&P)'!A3 -> Albania | B10: =VLOOKUP(A10,'Regional lookup table'!$A$2:$B$162,2,FALSE()) -> Eastern Europe & Russia | C10: =VLOOKUP(A10,'Sovereign Ratings (Moody''s,S&P)'!$A$2:$D$158,4,FALSE()) -> Ba3 | D10: =VLOOKUP(C10,$J$10:$K$32,2,FALSE())/10000 -> 0.030563925 | E10: =$E$3+F10 -> 0.088860415 | F10: =IF($E$5="Yes",D10*$E$6,D10) -> 0.046560415 | G10: =VLOOKUP(A10,'10-year CDS Spreads'!$A$2:$D$158,4,FALSE()) -> NA | H10: =IF(I10="NA","NA",$E$3+I10) -> NA | I10: =IF(G10="NA","NA",G10*$E$6) -> NA | J10: A1 | K10: =C191 -> 59.929264
A11: ='Sovereign Ratings (Moody''s,S&P)'!A4 -> Andorra (Principality of) | B11: =VLOOKUP(A11,'Regional lookup table'!$A$2:$B$162,2,FALSE()) -> Western Europe | C11: =VLOOKUP(A11,'Sovereign Ratings (Moody''s,S&P)'!$A$2:$D$158,4,FALSE()) -> Baa1 | D11: =VLOOKUP(C11,$J$10:$K$32,2,FALSE())/10000 -> 0.013583967 | E11: =$E$3+F11 -> 0.062993518 | F11: =IF($E$5="Yes",D11*$E$6,D11) -> 0.020693518 | G11: =VLOOKUP(A11,'10-year CDS Spreads'!$A$2:$D$158,4,FALSE()) -> NA | H11: =IF(I11="NA","NA",$E$3+I11) -> NA | I11: =IF(G11="NA","NA",G11*$E$6) -> NA | J11: A2 | K11: =C192 -> 71.915117
A12: ='Sovereign Ratings (Moody''s,S&P)'!A5 -> Angola | B12: =VLOOKUP(A12,'Regional lookup table'!$A$2:$B$162,2,FALSE()) -> Africa | C12: =VLOOKUP(A12,'Sovereign Ratings (Moody''s,S&P)'!$A$2:$D$158,4,FALSE()) -> B3 | D12: =VLOOKUP(C12,$J$10:$K$32,2,FALSE())/10000 -> 0.055234805 | E12: =$E$3+F12 -> 0.12644349 | F12: =IF($E$5="Yes",D12*$E$6,D12) -> 0.084143495 | G12: =VLOOKUP(A12,'10-year CDS Spreads'!$A$2:$D$158,4,FALSE()) -> 0.061 | H12: =IF(I12="NA","NA",$E$3+I12) -> 0.13522607 | I12: =IF(G12="NA","NA",G12*$E$6) -> 0.092926066 | J12: A3 | K12: =C193 -> 101.87975
A13: ='Sovereign Ratings (Moody''s,S&P)'!A6 -> Argentina | B13: =VLOOKUP(A13,'Regional lookup table'!$A$2:$B$162,2,FALSE()) -> Central and South America | C13: =VLOOKUP(A13,'Sovereign Ratings (Moody''s,S&P)'!$A$2:$D$158,4,FALSE()) -> Caa1 | D13: =VLOOKUP(C13,$J$10:$K$32,2,FALSE())/10000 -> 0.063724785 | E13: =$E$3+F13 -> 0.13937694 | F13: =IF($E$5="Yes",D13*$E$6,D13) -> 0.097076943 | G13: =VLOOKUP(A13,'10-year CDS Spreads'!$A$2:$D$158,4,FALSE()) -> NA | H13: =IF(I13="NA","NA",$E$3+I13) -> NA | I13: =IF(G13="NA","NA",G13*$E$6) -> NA | J13: Aa1 | K13: =C194 -> 23.336792
A14: ='Sovereign Ratings (Moody''s,S&P)'!A7 -> Armenia | B14: =VLOOKUP(A14,'Regional lookup table'!$A$2:$B$162,2,FALSE()) -> Eastern Europe & Russia | C14: =VLOOKUP(A14,'Sovereign Ratings (Moody''s,S&P)'!$A$2:$D$158,4,FALSE()) -> Ba3 | D14: =VLOOKUP(C14,$J$10:$K$32,2,FALSE())/10000 -> 0.030563925 | E14: =$E$3+F14 -> 0.088860415 | F14: =IF($E$5="Yes",D14*$E$6,D14) -> 0.046560415 | G14: =VLOOKUP(A14,'10-year CDS Spreads'!$A$2:$D$158,4,FALSE()) -> NA | H14: =IF(I14="NA","NA",$E$3+I14) -> NA | I14: =IF(G14="NA","NA",G14*$E$6) -> NA | J14: Aa2 | K14: =C195 -> 41.950485
A15: ='Sovereign Ratings (Moody''s,S&P)'!A8 -> Aruba | B15: =VLOOKUP(A15,'Regional lookup table'!$A$2:$B$162,2,FALSE()) -> Caribbean | C15: =VLOOKUP(A15,'Sovereign Ratings (Moody''s,S&P)'!$A$2:$D$158,4,FALSE()) -> Baa3 | D15: =VLOOKUP(C15,$J$10:$K$32,2,FALSE())/10000 -> 0.018677954 | E15: =$E$3+F15 -> 0.070753587 | F15: =IF($E$5="Yes",D15*$E$6,D15) -> 0.028453587 | G15: =VLOOKUP(A15,'10-year CDS Spreads'!$A$2:$D$158,4,FALSE()) -> NA | H15: =IF(I15="NA","NA",$E$3+I15) -> NA | I15: =IF(G15="NA","NA",G15*$E$6) -> NA | J15: Aa3 | K15: =C196 -> 50.939875
A16: ='Sovereign Ratings (Moody''s,S&P)'!A9 -> Australia | B16: =VLOOKUP(A16,'Regional lookup table'!$A$2:$B$162,2,FALSE()) -> Australia & New Zealand | C16: =VLOOKUP(A16,'Sovereign Ratings (Moody''s,S&P)'!$A$2:$D$158,4,FALSE()) -> Aaa | D16: =VLOOKUP(C16,$J$10:$K$32,2,FALSE())/10000 -> 0 | E16: =$E$3+F16 -> 0.0423 | F16: =IF($E$5="Yes",D16*$E$6,D16) -> 0 | G16: =VLOOKUP(A16,'10-year CDS Spreads'!$A$2:$D$158,4,FALSE()) -> 0.0005 | H16: =IF(I16="NA","NA",$E$3+I16) -> 0.043061689 | I16: =IF(G16="NA","NA",G16*$E$6) -> 0.00076168907 | J16: Aaa | K16: =C197 -> 0
A17: ='Sovereign Ratings (Moody''s,S&P)'!A10 -> Austria | B17: =VLOOKUP(A17,'Regional lookup table'!$A$2:$B$162,2,FALSE()) -> Western Europe | C17: =VLOOKUP(A17,'Sovereign Ratings (Moody''s,S&P)'!$A$2:$D$158,4,FALSE()) -> Aa1 | D17: =VLOOKUP(C17,$J$10:$K$32,2,FALSE())/10000 -> 0.0023336792 | E17: =$E$3+F17 -> 0.045855076 | F17: =IF($E$5="Yes",D17*$E$6,D17) -> 0.0035550758 | G17: =VLOOKUP(A17,'10-year CDS Spreads'!$A$2:$D$158,4,FALSE()) -> 0.0014 | H17: =IF(I17="NA","NA",$E$3+I17) -> 0.044432729 | I17: =IF(G17="NA","NA",G17*$E$6) -> 0.0021327294 | J17: B1 | K17: =C198 -> 382.54847
A18: ='Sovereign Ratings (Moody''s,S&P)'!A11 -> Azerbaijan | B18: =VLOOKUP(A18,'Regional lookup table'!$A$2:$B$162,2,FALSE()) -> Eastern Europe & Russia | C18: =VLOOKUP(A18,'Sovereign Ratings (Moody''s,S&P)'!$A$2:$D$158,4,FALSE()) -> Baa3 | D18: =VLOOKUP(C18,$J$10:$K$32,2,FALSE())/10000 -> 0.018677954 | E18: =$E$3+F18 -> 0.070753587 | F18: =IF($E$5="Yes",D18*$E$6,D18) -> 0.028453587 | G18: =VLOOKUP(A18,'10-year CDS Spreads'!$A$2:$D$158,4,FALSE()) -> NA | H18: =IF(I18="NA","NA",$E$3+I18) -> NA | I18: =IF(G18="NA","NA",G18*$E$6) -> NA | J18: B2 | K18: =C199 -> 467.44826
A19: ='Sovereign Ratings (Moody''s,S&P)'!A12 -> Bahamas | B19: =VLOOKUP(A19,'Regional lookup table'!$A$2:$B$162,2,FALSE()) -> Caribbean | C19: =VLOOKUP(A19,'Sovereign Ratings (Moody''s,S&P)'!$A$2:$D$158,4,FALSE()) -> B1 | D19: =VLOOKUP(C19,$J$10:$K$32,2,FALSE())/10000 -> 0.038254847 | E19: =$E$3+F19 -> 0.1005766 | F19: =IF($E$5="Yes",D19*$E$6,D19) -> 0.058276598 | G19: =VLOOKUP(A19,'10-year CDS Spreads'!$A$2:$D$158,4,FALSE()) -> NA | H19: =IF(I19="NA","NA",$E$3+I19) -> NA | I19: =IF(G19="NA","NA",G19*$E$6) -> NA | J19: B3 | K19: =C200 -> 552.34805
A20: ='Sovereign Ratings (Moody''s,S&P)'!A13 -> Bahrain | B20: =VLOOKUP(A20,'Regional lookup table'!$A$2:$B$162,2,FALSE()) -> Middle East | C20: =VLOOKUP(A20,'Sovereign Ratings (Moody''s,S&P)'!$A$2:$D$158,4,FALSE()) -> B2 | D20: =VLOOKUP(C20,$J$10:$K$32,2,FALSE())/10000 -> 0.046744826 | E20: =$E$3+F20 -> 0.11351005 | F20: =IF($E$5="Yes",D20*$E$6,D20) -> 0.071210046 | G20: =VLOOKUP(A20,'10-year CDS Spreads'!$A$2:$D$158,4,FALSE()) -> 0.0233 | H20: =IF(I20="NA","NA",$E$3+I20) -> 0.07779471 | I20: =IF(G20="NA","NA",G20*$E$6) -> 0.03549471 | J20: Ba1 | K20: =C201 -> 212.74889
A21: ='Sovereign Ratings (Moody''s,S&P)'!A14 -> Bangladesh | B21: =VLOOKUP(A21,'Regional lookup table'!$A$2:$B$162,2,FALSE()) -> Asia | C21: =VLOOKUP(A21,'Sovereign Ratings (Moody''s,S&P)'!$A$2:$D$158,4,FALSE()) -> B2 | D21: =VLOOKUP(C21,$J$10:$K$32,2,FALSE())/10000 -> 0.046744826 | E21: =$E$3+F21 -> 0.11351005 | F21: =IF($E$5="Yes",D21*$E$6,D21) -> 0.071210046 | G21: =VLOOKUP(A21,'10-year CDS Spreads'!$A$2:$D$158,4,FALSE()) -> NA | H21: =IF(I21="NA","NA",$E$3+I21) -> NA | I21: =IF(G21="NA","NA",G21*$E$6) -> NA | J21: Ba2 | K21: =C202 -> 255.69819
... A27: ='Sovereign Ratings (Moody''s,S&P)'!A20 -> Bermuda | B27: =VLOOKUP(A27,'Regional lookup table'!$A$2:$B$162,2,FALSE()) -> Caribbean | C27: =VLOOKUP(A27,'Sovereign Ratings (Moody''s,S&P)'!$A$2:$D$158,4,FALSE()) -> A2 | D27: =VLOOKUP(C27,$J$10:$K$32,2,FALSE())/10000 -> 0.0071915117 | E27: =$E$3+F27 -> 0.053255392 | F27: =IF($E$5="Yes",D27*$E$6,D27) -> 0.010955392 | G27: =VLOOKUP(A27,'10-year CDS Spreads'!$A$2:$D$158,4,FALSE()) -> NA | H27: =IF(I27="NA","NA",$E$3+I27) -> NA | I27: =IF(G27="NA","NA",G27*$E$6) -> NA | J27: Ca | K27: =C208 -> 1019.7963
A28: ='Sovereign Ratings (Moody''s,S&P)'!A21 -> Bolivia | B28: =VLOOKUP(A28,'Regional lookup table'!$A$2:$B$162,2,FALSE()) -> Central and South America | C28: =VLOOKUP(A28,'Sovereign Ratings (Moody''s,S&P)'!$A$2:$D$158,4,FALSE()) -> Ca | D28: =VLOOKUP(C28,$J$10:$K$32,2,FALSE())/10000 -> 0.10197963 | E28: =$E$3+F28 -> 0.19765354 | F28: =IF($E$5="Yes",D28*$E$6,D28) -> 0.15535354 | G28: =VLOOKUP(A28,'10-year CDS Spreads'!$A$2:$D$158,4,FALSE()) -> NA | H28: =IF(I28="NA","NA",$E$3+I28) -> NA | I28: =IF(G28="NA","NA",G28*$E$6) -> NA | J28: =B209 -> Caa1 | K28: =C209 -> 637.24785
A29: ='Sovereign Ratings (Moody''s,S&P)'!A22 -> Bosnia and Herzegovina | B29: =VLOOKUP(A29,'Regional lookup table'!$A$2:$B$162,2,FALSE()) -> Eastern Europe & Russia | C29: =VLOOKUP(A29,'Sovereign Ratings (Moody''s,S&P)'!$A$2:$D$158,4,FALSE()) -> B3 | D29: =VLOOKUP(C29,$J$10:$K$32,2,FALSE())/10000 -> 0.055234805 | E29: =$E$3+F29 -> 0.12644349 | F29: =IF($E$5="Yes",D29*$E$6,D29) -> 0.084143495 | G29: =VLOOKUP(A29,'10-year CDS Spreads'!$A$2:$D$158,4,FALSE()) -> NA | H29: =IF(I29="NA","NA",$E$3+I29) -> NA | I29: =IF(G29="NA","NA",G29*$E$6) -> NA | J29: =B210 -> Caa2 | K29: =C210 -> 765.09694
A30: ='Sovereign Ratings (Moody''s,S&P)'!A23 -> Botswana | B30: =VLOOKUP(A30,'Regional lookup table'!$A$2:$B$162,2,FALSE()) -> Africa | C30: =VLOOKUP(A30,'Sovereign Ratings (Moody''s,S&P)'!$A$2:$D$158,4,FALSE()) -> Baa1 | D30: =VLOOKUP(C30,$J$10:$K$32,2,FALSE())/10000 -> 0.013583967 | E30: =$E$3+F30 -> 0.062993518 | F30: =IF($E$5="Yes",D30*$E$6,D30) -> 0.020693518 | G30: =VLOOKUP(A30,'10-year CDS Spreads'!$A$2:$D$158,4,FALSE()) -> NA | H30: =IF(I30="NA","NA",$E$3+I30) -> NA | I30: =IF(G30="NA","NA",G30*$E$6) -> NA | J30: =B211 -> Caa3 | K30: =C211 -> 849.99673
A31: ='Sovereign Ratings (Moody''s,S&P)'!A24 -> Brazil | B31: =VLOOKUP(A31,'Regional lookup table'!$A$2:$B$162,2,FALSE()) -> Central and South America | C31: =VLOOKUP(A31,'Sovereign Ratings (Moody''s,S&P)'!$A$2:$D$158,4,FALSE()) -> Ba1 | D31: =VLOOKUP(C31,$J$10:$K$32,2,FALSE())/10000 -> 0.021274889 | E31: =$E$3+F31 -> 0.0747097 | F31: =IF($E$5="Yes",D31*$E$6,D31) -> 0.0324097 | G31: =VLOOKUP(A31,'10-year CDS Spreads'!$A$2:$D$158,4,FALSE()) -> 0.0221 | H31: =IF(I31="NA","NA",$E$3+I31) -> 0.075966657 | I31: =IF(G31="NA","NA",G31*$E$6) -> 0.033666657 | J31: NR | K31: =C212 -> NA
A32: ='Sovereign Ratings (Moody''s,S&P)'!A25 -> Bulgaria | B32: =VLOOKUP(A32,'Regional lookup table'!$A$2:$B$162,2,FALSE()) -> Eastern Europe & Russia | C32: =VLOOKUP(A32,'Sovereign Ratings (Moody''s,S&P)'!$A$2:$D$158,4,FALSE()) -> Baa1 | D32: =VLOOKUP(C32,$J$10:$K$32,2,FALSE())/10000 -> 0.013583967 | E32: =$E$3+F32 -> 0.062993518 | F32: =IF($E$5="Yes",D32*$E$6,D32) -> 0.020693518 | G32: =VLOOKUP(A32,'10-year CDS Spreads'!$A$2:$D$158,4,FALSE()) -> 0.0063 | H32: =IF(I32="NA","NA",$E$3+I32) -> 0.051897282 | I32: =IF(G32="NA","NA",G32*$E$6) -> 0.0095972822
A33: ='Sovereign Ratings (Moody''s,S&P)'!A26 -> Burkina Faso | B33: =VLOOKUP(A33,'Regional lookup table'!$A$2:$B$162,2,FALSE()) -> Africa | C33: =VLOOKUP(A33,'Sovereign Ratings (Moody''s,S&P)'!$A$2:$D$158,4,FALSE()) -> Caa1 | D33: =VLOOKUP(C33,$J$10:$K$32,2,FALSE())/10000 -> 0.063724785 | E33: =$E$3+F33 -> 0.13937694 | F33: =IF($E$5="Yes",D33*$E$6,D33) -> 0.097076943 | G33: =VLOOKUP(A33,'10-year CDS Spreads'!$A$2:$D$158,4,FALSE()) -> NA | H33: =IF(I33="NA","NA",$E$3+I33) -> NA | I33: =IF(G33="NA","NA",G33*$E$6) -> NA
A34: ='Sovereign Ratings (Moody''s,S&P)'!A27 -> Cambodia | B34: =VLOOKUP(A34,'Regional lookup table'!$A$2:$B$162,2,FALSE()) -> Asia | C34: =VLOOKUP(A34,'Sovereign Ratings (Moody''s,S&P)'!$A$2:$D$158,4,FALSE()) -> B2 | D34: =VLOOKUP(C34,$J$10:$K$32,2,FALSE())/10000 -> 0.046744826 | E34: =$E$3+F34 -> 0.11351005 | F34: =IF($E$5="Yes",D34*$E$6,D34) -> 0.071210046 | G34: =VLOOKUP(A34,'10-year CDS Spreads'!$A$2:$D$158,4,FALSE()) -> NA | H34: =IF(I34="NA","NA",$E$3+I34) -> NA | I34: =IF(G34="NA","NA",G34*$E$6) -> NA
A35: ='Sovereign Ratings (Moody''s,S&P)'!A28 -> Cameroon | B35: =VLOOKUP(A35,'Regional lookup table'!$A$2:$B$162,2,FALSE()) -> Africa | C35: =VLOOKUP(A35,'Sovereign Ratings (Moody''s,S&P)'!$A$2:$D$158,4,FALSE()) -> Caa1 | D35: =VLOOKUP(C35,$J$10:$K$32,2,FALSE())/10000 -> 0.063724785 | E35: =$E$3+F35 -> 0.13937694 | F35: =IF($E$5="Yes",D35*$E$6,D35) -> 0.097076943 | G35: =VLOOKUP(A35,'10-year CDS Spreads'!$A$2:$D$158,4,FALSE()) -> 0.0673 | H35: =IF(I35="NA","NA",$E$3+I35) -> 0.14482335 | I35: =IF(G35="NA","NA",G35*$E$6) -> 0.10252335
A36: ='Sovereign Ratings (Moody''s,S&P)'!A29 -> Canada | B36: =VLOOKUP(A36,'Regional lookup table'!$A$2:$B$162,2,FALSE()) -> North America | C36: =VLOOKUP(A36,'Sovereign Ratings (Moody''s,S&P)'!$A$2:$D$158,4,FALSE()) -> Aaa | D36: =VLOOKUP(C36,$J$10:$K$32,2,FALSE())/10000 -> 0 | E36: =$E$3+F36 -> 0.0423 | F36: =IF($E$5="Yes",D36*$E$6,D36) -> 0 | G36: =VLOOKUP(A36,'10-year CDS Spreads'!$A$2:$D$158,4,FALSE()) -> 0.0019 | H36: =IF(I36="NA","NA",$E$3+I36) -> 0.045194418 | I36: =IF(G36="NA","NA",G36*$E$6) -> 0.0028944185
A37: ='Sovereign Ratings (Moody''s,S&P)'!A30 -> Cape Verde | B37: =VLOOKUP(A37,'Regional lookup table'!$A$2:$B$162,2,FALSE()) -> Africa | C37: =VLOOKUP(A37,'Sovereign Ratings (Moody''s,S&P)'!$A$2:$D$158,4,FALSE()) -> B2 | D37: =VLOOKUP(C37,$J$10:$K$32,2,FALSE())/10000 -> 0.046744826 | E37: =$E$3+F37 -> 0.11351005 | F37: =IF($E$5="Yes",D37*$E$6,D37) -> 0.071210046 | G37: =VLOOKUP(A37,'10-year CDS Spreads'!$A$2:$D$158,4,FALSE()) -> NA | H37: =IF(I37="NA","NA",$E$3+I37) -> NA | I37: =IF(G37="NA","NA",G37*$E$6) -> NA
A38: ='Sovereign Ratings (Moody''s,S&P)'!A31 -> Cayman Islands | B38: =VLOOKUP(A38,'Regional lookup table'!$A$2:$B$162,2,FALSE()) -> Caribbean | C38: =VLOOKUP(A38,'Sovereign Ratings (Moody''s,S&P)'!$A$2:$D$158,4,FALSE()) -> Aa3 | D38: =VLOOKUP(C38,$J$10:$K$32,2,FALSE())/10000 -> 0.0050939875 | E38: =$E$3+F38 -> 0.050060069 | F38: =IF($E$5="Yes",D38*$E$6,D38) -> 0.0077600691 | G38: =VLOOKUP(A38,'10-year CDS Spreads'!$A$2:$D$158,4,FALSE()) -> NA | H38: =IF(I38="NA","NA",$E$3+I38) -> NA | I38: =IF(G38="NA","NA",G38*$E$6) -> NA
A39: ='Sovereign Ratings (Moody''s,S&P)'!A32 -> Chile | B39: =VLOOKUP(A39,'Regional lookup table'!$A$2:$B$162,2,FALSE()) -> Central and South America | C39: =VLOOKUP(A39,'Sovereign Ratings (Moody''s,S&P)'!$A$2:$D$158,4,FALSE()) -> A2 | D39: =VLOOKUP(C39,$J$10:$K$32,2,FALSE())/10000 -> 0.0071915117 | E39: =$E$3+F39 -> 0.053255392 | F39: =IF($E$5="Yes",D39*$E$6,D39) -> 0.010955392 | G39: =VLOOKUP(A39,'10-year CDS Spreads'!$A$2:$D$158,4,FALSE()) -> 0.0073 | H39: =IF(I39="NA","NA",$E$3+I39) -> 0.05342066 | I39: =IF(G39="NA","NA",G39*$E$6) -> 0.01112066
A40: ='Sovereign Ratings (Moody''s,S&P)'!A33 -> China | B40: =VLOOKUP(A40,'Regional lookup table'!$A$2:$B$162,2,FALSE()) -> Asia | C40: =VLOOKUP(A40,'Sovereign Ratings (Moody''s,S&P)'!$A$2:$D$158,4,FALSE()) -> A1 | D40: =VLOOKUP(C40,$J$10:$K$32,2,FALSE())/10000 -> 0.0059929264 | E40: =$E$3+F40 -> 0.051429493 | F40: =IF($E$5="Yes",D40*$E$6,D40) -> 0.0091294931 | G40: =VLOOKUP(A40,'10-year CDS Spreads'!$A$2:$D$158,4,FALSE()) -> 0.005 | H40: =IF(I40="NA","NA",$E$3+I40) -> 0.049916891 | I40: =IF(G40="NA","NA",G40*$E$6) -> 0.0076168907
A41: ='Sovereign Ratings (Moody''s,S&P)'!A34 -> Colombia | B41: =VLOOKUP(A41,'Regional lookup table'!$A$2:$B$162,2,FALSE()) -> Central and South America | C41: =VLOOKUP(A41,'Sovereign Ratings (Moody''s,S&P)'!$A$2:$D$158,4,FALSE()) -> Baa3 | D41: =VLOOKUP(C41,$J$10:$K$32,2,FALSE())/10000 -> 0.018677954 | E41: =$E$3+F41 -> 0.070753587 | F41: =IF($E$5="Yes",D41*$E$6,D41) -> 0.028453587 | G41: =VLOOKUP(A41,'10-year CDS Spreads'!$A$2:$D$158,4,FALSE()) -> 0.032 | H41: =IF(I41="NA","NA",$E$3+I41) -> 0.0910481 | I41: =IF(G41="NA","NA",G41*$E$6) -> 0.0487481
A42: ='Sovereign Ratings (Moody''s,S&P)'!A35 -> Congo (Democratic Republic of) | B42: =VLOOKUP(A42,'Regional lookup table'!$A$2:$B$162,2,FALSE()) -> Africa | C42: =VLOOKUP(A42,'Sovereign Ratings (Moody''s,S&P)'!$A$2:$D$158,4,FALSE()) -> B3 | D42: =VLOOKUP(C42,$J$10:$K$32,2,FALSE())/10000 -> 0.055234805 | E42: =$E$3+F42 -> 0.12644349 | F42: =IF($E$5="Yes",D42*$E$6,D42) -> 0.084143495 | G42: =VLOOKUP(A42,'10-year CDS Spreads'!$A$2:$D$158,4,FALSE()) -> NA | H42: =IF(I42="NA","NA",$E$3+I42) -> NA | I42: =IF(G42="NA","NA",G42*$E$6) -> NA
A43: ='Sovereign Ratings (Moody''s,S&P)'!A36 -> Congo (Republic of) | B43: =VLOOKUP(A43,'Regional lookup table'!$A$2:$B$162,2,FALSE()) -> Africa | C43: =VLOOKUP(A43,'Sovereign Ratings (Moody''s,S&P)'!$A$2:$D$158,4,FALSE()) -> Caa2 | D43: =VLOOKUP(C43,$J$10:$K$32,2,FALSE())/10000 -> 0.076509694 | E43: =$E$3+F43 -> 0.1588532 | F43: =IF($E$5="Yes",D43*$E$6,D43) -> 0.1165532 | G43: =VLOOKUP(A43,'10-year CDS Spreads'!$A$2:$D$158,4,FALSE()) -> NA | H43: =IF(I43="NA","NA",$E$3+I43) -> NA | I43: =IF(G43="NA","NA",G43*$E$6) -> NA
... A159: ='Sovereign Ratings (Moody''s,S&P)'!A152 -> United Kingdom | B159: =VLOOKUP(A159,'Regional lookup table'!$A$2:$B$162,2,FALSE()) -> Western Europe | C159: =VLOOKUP(A159,'Sovereign Ratings (Moody''s,S&P)'!$A$2:$D$158,4,FALSE()) -> Aa3 | D159: =VLOOKUP(C159,$J$10:$K$32,2,FALSE())/10000 -> 0.0050939875 | E159: =$E$3+F159 -> 0.050060069 | F159: =IF($E$5="Yes",D159*$E$6,D159) -> 0.0077600691 | G159: =VLOOKUP(A159,'10-year CDS Spreads'!$A$2:$D$158,4,FALSE()) -> 0.0023 | H159: =IF(I159="NA","NA",$E$3+I159) -> 0.04580377 | I159: =IF(G159="NA","NA",G159*$E$6) -> 0.0035037697
A160: ='Sovereign Ratings (Moody''s,S&P)'!A153 -> United States | B160: =VLOOKUP(A160,'Regional lookup table'!$A$2:$B$162,2,FALSE()) -> North America | C160: =VLOOKUP(A160,'Sovereign Ratings (Moody''s,S&P)'!$A$2:$D$158,4,FALSE()) -> Aa1 | D160: =VLOOKUP(C160,$J$10:$K$32,2,FALSE())/10000 -> 0.0023336792 | E160: =E4 -> 0.0446 | F160: =IF($E$5="Yes",D160,D160) -> 0.0023336792 | G160: =VLOOKUP(A160,'10-year CDS Spreads'!$A$2:$D$158,4,FALSE()) -> 0.003 | H160: =IF(I160="NA","NA",$E$3+I160) -> 0.046870134 | I160: =IF(G160="NA","NA",G160*$E$6) -> 0.0045701344
A161: ='Sovereign Ratings (Moody''s,S&P)'!A154 -> Uruguay | B161: =VLOOKUP(A161,'Regional lookup table'!$A$2:$B$162,2,FALSE()) -> Central and South America | C161: =VLOOKUP(A161,'Sovereign Ratings (Moody''s,S&P)'!$A$2:$D$158,4,FALSE()) -> Baa1 | D161: =VLOOKUP(C161,$J$10:$K$32,2,FALSE())/10000 -> 0.013583967 | E161: =$E$3+F161 -> 0.062993518 | F161: =IF($E$5="Yes",D161*$E$6,D161) -> 0.020693518 | G161: =VLOOKUP(A161,'10-year CDS Spreads'!$A$2:$D$158,4,FALSE()) -> 0.0063 | H161: =IF(I161="NA","NA",$E$3+I161) -> 0.051897282 | I161: =IF(G161="NA","NA",G161*$E$6) -> 0.0095972822
...

Sheet Relative Equity Volatility
A1: Year | B1: Std Dev (BMI) | C1: Std Dev (JPM Sov Bond) | D1: REL VOL | J1: Estimation note: Those of you who have followed my attempts to estimate the relative equity market volatility know that I have struggled with getting a proxy for returns on emerging market sovereign bonds, and have used the coefficient of varation in yields to make that estimate. I have finally replaced that estimate with a return on an emerging market government bond ETF from iShares. The standard deviations are now computed consistently for emerigng equities and emerigng government bonds. (Using the old yield coefficient of variation approach would have yielded a ratio of 1.49 in this computation.)
A2: 2021 | B2: =STDEV(I15:I276)*(261^0.5) -> 0.14315335 | C2: =STDEV(C15:C267)*(252^0.5) -> 0.068728637 | D2: =B2/C2 -> 2.0828778
A3: 2022 | B3: =STDEV(I277:I536)*(259^0.5) -> 0.18634568 | C3: =STDEV(C268:C518)*(250^0.5) -> 0.15379759 | D3: =B3/C3 -> 1.2116294
A4: 2023 | B4: =STDEV(I537:I796)*(259^0.5) -> 0.11141327 | C4: =STDEV(C519:C768)*(249^0.5) -> 0.098673761 | D4: =B4/C4 -> 1.1291074
A5: 2024 | B5: =STDEV(I797:I1058)*(261^0.5) -> 0.11865915 | C5: =STDEV(C769:C1020)*(251^0.5) -> 0.074136944 | D5: =B5/C5 -> 1.60054
A6: 2025 | B6: =STDEV(I1059:I1319)*(260^0.5) -> 0.14611177 | C6: =STDEV(C1021:C1270)*(249^0.5) -> 0.067898827 | D6: =B6/C6 -> 2.1519042
A7: Average Relative Volatility | B7: =AVERAGE(B2:B6) -> 0.14113664 | C7: =AVERAGE(C2:C6) -> 0.092647151 | D7: =B7/C7 -> 1.5233781
A9: Index: | B9: iShares JP Morgan USD Emerging Markets Bond ETF | G9: Index: | H9: S&P Emerging BMI Index
A10: Source: | B10: Yahoo! | G10: Source: | H10: S&P
B11: https://finance.yahoo.com/quote/EMB/ | H11: https://www.spglobal.com/spdji/en/indices/equity/sp-emerging-bmi/#overview
A12: Period | B12: Five years | C12: (Dec 31, 2020 - Dec 31, 2025) | G12: Period | H12: Five years | I12: (Dec 31, 2020 - Dec 31, 2025)
A13: Interval | B13: Daily | G13: Interval | H13: Daily
A14: Date | B14: Close | C14: Return | G14: Effective date | H14: S&P Emerging BMI (USD) | I14: Return
A15: 42734 | B15: 115.91 | G15: 42734 | H15: 331.34
A16: 42738 | B16: 115.27 | C16: =B16/B15-1 -> -0.0055215253 | G16: 42735 | H16: 331.57 | I16: =H16/H15-1 -> 0.00069415102
A17: 42739 | B17: 115.35 | C17: =B17/B16-1 -> 0.00069402273 | G17: 42738 | H17: 334.34 | I17: =H17/H16-1 -> 0.0083541937
A18: 42740 | B18: 114.52 | C18: =B18/B17-1 -> -0.007195492 | G18: 42739 | H18: 337.8 | I18: =H18/H17-1 -> 0.010348747
A19: 42741 | B19: 114.48 | C19: =B19/B18-1 -> -0.00034928397 | G19: 42740 | H19: 336.87 | I19: =H19/H18-1 -> -0.0027531083
A20: 42742 | B20: 114.54 | C20: =B20/B19-1 -> 0.00052410901 | G20: 42741 | H20: 337.98 | I20: =H20/H19-1 -> 0.0032950396
A21: 42745 | B21: 113.64 | C21: =B21/B20-1 -> -0.007857517 | G21: 42742 | H21: 343.78 | I21: =H21/H20-1 -> 0.017160779
A22: 42746 | B22: 113.1 | C22: =B22/B21-1 -> -0.0047518479 | G22: 42745 | H22: 342.48 | I22: =H22/H21-1 -> -0.0037814882
A23: 42747 | B23: 113.63 | C23: =B23/B22-1 -> 0.0046861185 | G23: 42746 | H23: 344.33 | I23: =H23/H22-1 -> 0.0054017753
A24: 42748 | B24: 113.3 | C24: =B24/B23-1 -> -0.0029041626 | G24: 42747 | H24: 346.61 | I24: =H24/H23-1 -> 0.0066215549
A25: 42749 | B25: 113.43 | C25: =B25/B24-1 -> 0.0011473963 | G25: 42748 | H25: 348.89 | I25: =H25/H24-1 -> 0.0065779983
A26: 42753 | B26: 113.59 | C26: =B26/B25-1 -> 0.0014105616 | G26: 42749 | H26: 346.19 | I26: =H26/H25-1 -> -0.0077388289
A27: 42754 | B27: 113.72 | C27: =B27/B26-1 -> 0.0011444669 | G27: 42752 | H27: 347.78 | I27: =H27/H26-1 -> 0.0045928536
... A1270: 44560 | B1270: 96.28 | C1270: =B1270/B1269-1 -> -0.0019695242 | G1270: 44491 | H1270: 368.92 | I1270: =H1270/H1269-1 -> 0.0026634777
G1271: 44492 | H1271: 370.04 | I1271: =H1271/H1270-1 -> 0.0030358885
G1272: 44495 | H1272: 373.91 | I1272: =H1272/H1271-1 -> 0.010458329
G1273: 44496 | H1273: 373.25 | I1273: =H1273/H1272-1 -> -0.0017651306
G1274: 44497 | H1274: 375.51 | I1274: =H1274/H1273-1 -> 0.006054923
G1275: 44498 | H1275: 373.69 | I1275: =H1275/H1274-1 -> -0.0048467418
G1276: 44499 | H1276: 370.73 | I1276: =H1276/H1275-1 -> -0.007921004
G1277: 44502 | H1277: 371.77 | I1277: =H1277/H1276-1 -> 0.0028052761
G1278: 44503 | H1278: 368.33 | I1278: =H1278/H1277-1 -> -0.0092530328
G1279: 44504 | H1279: 367.59 | I1279: =H1279/H1278-1 -> -0.002009068
G1280: 44505 | H1280: 370.25 | I1280: =H1280/H1279-1 -> 0.0072363231
G1281: 44506 | H1281: 367.93 | I1281: =H1281/H1280-1 -> -0.0062660365
G1282: 44509 | H1282: 371.25 | I1282: =H1282/H1281-1 -> 0.0090234555
... G1319: 44560 | H1319: 369.16 | I1319: =H1319/H1318-1 -> 0.0018182312

Sheet Regional Simple Averages
B3: Data
A4: Region | B4: Average of Adj. Default Spread | C4: Average of Country Risk Premium | D4: Average of Equity Risk Premium | E4: Average of Corporate Tax Rate
A5: Africa | B5: 0.054199361 | C5: 0.082566121 | D5: 0.12486612 | E5: 0.27590667
A6: Asia | B6: 0.031733378 | C6: 0.048341934 | D6: 0.090641934 | E6: 0.240475
A7: Australia & New Zealand | B7: 0.012751616 | C7: 0.019425533 | D7: 0.061725533 | E7: 0.26
A8: Caribbean | B8: 0.03081363 | C8: 0.04694081 | D8: 0.08924081 | E8: 0.17714286
A9: Central and South America | B9: 0.045688523 | C9: 0.069600897 | D9: 0.1119009 | E9: 0.27131579
A10: Eastern Europe & Russia | B10: 0.032942139 | C10: 0.050183334 | D10: 0.092483334 | E10: 0.16423077
A11: Middle East | B11: 0.031033106 | C11: 0.047275155 | D11: 0.089575155 | E11: 0.14683077
A12: North America | B12: 0.0011668396 | C12: 0.0011668396 | D12: 0.04345 | E12: 0.2557
A13: Western Europe | B13: 0.0063068969 | C13: 0.0096077888 | D13: 0.051907789 | E13: 0.19943077
A14: Total Result | B14: 0.032812411 | C14: 0.04997793 | D14: 0.092277715 | E14: 0.21871975

Sheet Regional Weighted Averages
A1: Country | B1: GDP (in millions) in 2024 | C1: Moody's rating | D1: Adj. Default Spread | E1: Equity Risk Premium | F1: Country Risk Premium | G1: Corporate Tax Rate | H1: Region | I1: GDP Weight | J1: Weight*Default Spread | K1: Weight*ERP | L1: Weight*CRP | M1: Weight * Tax Rate
A2: Angola | B2: 100998.92 | C2: B3 | D2: 0.055234805 | E2: =F2+4.23% -> 0.12644349 | F2: 0.084143495 | G2: 0.25 | H2: Africa | I2: =B2/$B$32 -> 0.043145792 | J2: =I2*D2 -> 0.0023831494 | K2: =I2*E2 -> 0.0054555048 | L2: =I2*F2 -> 0.0036304378 | M2: =I2*G2 -> 0.010786448
A3: Benin | B3: 21482.644 | C3: B1 | D3: 0.038254847 | E3: =F3+4.23% -> 0.1005766 | F3: 0.058276598 | G3: 0.3 | H3: Africa | I3: =B3/$B$32 -> 0.0091771844 | J3: =I3*D3 -> 0.00035107179 | K3: =I3*E3 -> 0.00092300999 | L3: =I3*F3 -> 0.00053481508 | M3: =I3*G3 -> 0.0027531553
A4: Botswana | B4: 19402.064 | C4: Baa1 | D4: 0.013583967 | E4: =F4+4.23% -> 0.062993518 | F4: 0.020693518 | G4: 0.22 | H4: Africa | I4: =B4/$B$32 -> 0.00828838 | J4: =I4*D4 -> 0.00011258908 | K4: =I4*E4 -> 0.00052211421 | L4: =I4*F4 -> 0.00017151574 | M4: =I4*G4 -> 0.0018234436
A5: Burkina Faso | B5: 23124.73 | C5: Caa1 | D5: 0.063724785 | E5: =F5+4.23% -> 0.13937694 | F5: 0.097076943 | G5: 0.275 | H5: Africa | I5: =B5/$B$32 -> 0.0098786683 | J5: =I5*D5 -> 0.00062951601 | K5: =I5*E5 -> 0.0013768586 | L5: =I5*F5 -> 0.00095899092 | M5: =I5*G5 -> 0.0027166338
A6: Cameroon | B6: 53296.694 | C6: Caa1 | D6: 0.063724785 | E6: =F6+4.23% -> 0.13937694 | F6: 0.097076943 | G6: 0.33 | H6: Africa | I6: =B6/$B$32 -> 0.022767849 | J6: =I6*D6 -> 0.0014508763 | K6: =I6*E6 -> 0.0031733132 | L6: =I6*F6 -> 0.0022102332 | M6: =I6*G6 -> 0.0075133903
A7: Cape Verde | B7: 2725.4142 | C7: B2 | D7: 0.046744826 | E7: =F7+4.23% -> 0.11351005 | F7: 0.071210046 | G7: 0.2686 | H7: Africa | I7: =B7/$B$32 -> 0.0011642714 | J7: =I7*D7 -> 5.4423666e-05 | K7: =I7*E7 -> 0.0001321565 | L7: =I7*F7 -> 8.2907822e-05 | M7: =I7*G7 -> 0.00031272331
A8: Congo (Democratic Republic of) | B8: 70962.186 | C8: B3 | D8: 0.055234805 | E8: =F8+4.23% -> 0.12644349 | F8: 0.084143495 | G8: 0.3 | H8: Africa | I8: =B8/$B$32 -> 0.030314382 | J8: =I8*D8 -> 0.001674409 | K8: =I8*E8 -> 0.0038330564 | L8: =I8*F8 -> 0.002550758 | M8: =I8*G8 -> 0.0090943146
A9: Congo (Republic of) | B9: 15719.986 | C9: Caa2 | D9: 0.076509694 | E9: =F9+4.23% -> 0.1588532 | F9: 0.1165532 | G9: 0.2686 | H9: Africa | I9: =B9/$B$32 -> 0.006715431 | J9: =I9*D9 -> 0.00051379557 | K9: =I9*E9 -> 0.0010667677 | L9: =I9*F9 -> 0.00078270494 | M9: =I9*G9 -> 0.0018037648
A10: Côte d'Ivoire | B10: 87113.179 | C10: Ba2 | D10: 0.025569819 | E10: =F10+4.23% -> 0.081252504 | F10: 0.038952504 | G10: 0.25 | H10: Africa | I10: =B10/$B$32 -> 0.037213935 | J10: =I10*D10 -> 0.00095155361 | K10: =I10*E10 -> 0.0030237254 | L10: =I10*F10 -> 0.001449576 | M10: =I10*G10 -> 0.0093034838
A11: Egypt | B11: 389059.91 | C11: Caa1 | D11: 0.063724785 | E11: =F11+4.23% -> 0.13937694 | F11: 0.097076943 | G11: 0.225 | H11: Africa | I11: =B11/$B$32 -> 0.16620275 | J11: =I11*D11 -> 0.010591235 | K11: =I11*E11 -> 0.023164832 | L11: =I11*F11 -> 0.016134455 | M11: =I11*G11 -> 0.03739562
A12: Ethiopia | B12: 149740.3 | C12: Caa2 | D12: 0.076509694 | E12: =F12+4.23% -> 0.1588532 | F12: 0.1165532 | G12: 0.3 | H12: Africa | I12: =B12/$B$32 -> 0.063967655 | J12: =I12*D12 -> 0.0048941457 | K12: =I12*E12 -> 0.010161466 | L12: =I12*F12 -> 0.0074556345 | M12: =I12*G12 -> 0.019190296
A13: Gabon | B13: 20895.684 | C13: Caa2 | D13: 0.076509694 | E13: =F13+4.23% -> 0.1588532 | F13: 0.1165532 | G13: 0.3 | H13: Africa | I13: =B13/$B$32 -> 0.0089264409 | J13: =I13*D13 -> 0.00068295927 | K13: =I13*E13 -> 0.0014179937 | L13: =I13*F13 -> 0.0010404052 | M13: =I13*G13 -> 0.0026779323
... A31: Zambia | B31: 25303.185 | C31: Caa2 | D31: 0.076509694 | E31: =F31+4.23% -> 0.1588532 | F31: 0.1165532 | G31: 0.3 | H31: Africa | I31: =B31/$B$32 -> 0.010809284 | J31: =I31*D31 -> 0.00082701502 | K31: =I31*E31 -> 0.0017170893 | L31: =I31*F31 -> 0.0012598566 | M31: =I31*G31 -> 0.0032427852
A32: Africa | B32: =SUM(B2:B31) -> 2340875.2 | D32: =SUM(J2:J31) -> 0.050672304 | E32: =F32+4.23% -> 0.11949308 | F32: =SUM(L2:L31) -> 0.077193081 | G32: =SUM(M2:M31) -> 0.27390174 | I32: =SUM(I2:I31) -> 1
A33: Bangladesh | B33: 450119.43 | C33: B2 | D33: 0.046744826 | E33: =F33+4.23% -> 0.11351005 | F33: 0.071210046 | G33: 0.275 | H33: Asia | I33: =B33/$B$57 -> 0.012959906 | J33: =I33*D33 -> 0.00060580856 | K33: =I33*E33 -> 0.0014710795 | L33: =I33*F33 -> 0.00092287551 | M33: =I33*G33 -> 0.0035639742
A34: Cambodia | B34: 46352.647 | C34: B2 | D34: 0.046744826 | E34: =F34+4.23% -> 0.11351005 | F34: 0.071210046 | G34: 0.2 | H34: Asia | I34: =B34/$B$57 -> 0.0013345924 | J34: =I34*D34 -> 6.2385288e-05 | K34: =I34*E34 -> 0.00015148964 | L34: =I34*F34 -> 9.5036383e-05 | M34: =I34*G34 -> 0.00026691847
A35: China | B35: 18743803 | C35: A1 | D35: 0.0059929264 | E35: =F35+4.23% -> 0.051429493 | F35: 0.0091294931 | G35: 0.25 | H35: Asia | I35: =B35/$B$57 -> 0.53967439 | J35: =I35*D35 -> 0.0032342289 | K35: =I35*E35 -> 0.02775518 | L35: =I35*F35 -> 0.0049269536 | M35: =I35*G35 -> 0.1349186
A36: Fiji | B36: 5968.1259 | C36: B1 | D36: 0.038254847 | E36: =F36+4.23% -> 0.1005766 | F36: 0.058276598 | G36: 0.25 | H36: Asia | I36: =B36/$B$57 -> 0.00017183517 | J36: =I36*D36 -> 6.5735283e-06 | K36: =I36*E36 -> 1.7282597e-05 | L36: =I36*F36 -> 1.0013969e-05 | M36: =I36*G36 -> 4.2958794e-05
A37: Hong Kong | B37: 406863.4 | C37: Aa3 | D37: 0.0050939875 | E37: =F37+4.23% -> 0.050060069 | F37: 0.0077600691 | G37: 0.165 | H37: Asia | I37: =B37/$B$57 -> 0.011714472 | J37: =I37*D37 -> 5.9673373e-05 | K37: =I37*E37 -> 0.00058642727 | L37: =I37*F37 -> 9.0905111e-05 | M37: =I37*G37 -> 0.0019328879
A38: India | B38: 3909891.5 | C38: Baa3 | D38: 0.018677954 | E38: =F38+4.23% -> 0.070753587 | F38: 0.028453587 | G38: 0.3 | H38: Asia | I38: =B38/$B$57 -> 0.11257418 | J38: =I38*D38 -> 0.0021026554 | K38: =I38*E38 -> 0.0079650272 | L38: =I38*F38 -> 0.0032031393 | M38: =I38*G38 -> 0.033772255
A39: Indonesia | B39: 1396300.1 | C39: Baa2 | D39: 0.016180901 | E39: =F39+4.23% -> 0.066949631 | F39: 0.024649631 | G39: 0.22 | H39: Asia | I39: =B39/$B$57 -> 0.040202481 | J39: =I39*D39 -> 0.00065051239 | K39: =I39*E39 -> 0.0026915413 | L39: =I39*F39 -> 0.00099097635 | M39: =I39*G39 -> 0.0088445459
A40: Japan | B40: 4027597.5 | C40: A1 | D40: 0.0059929264 | E40: =F40+4.23% -> 0.051429493 | F40: 0.0091294931 | G40: 0.2974 | H40: Asia | I40: =B40/$B$57 -> 0.11596319 | J40: =I40*D40 -> 0.00069495887 | K40: =I40*E40 -> 0.0059639281 | L40: =I40*F40 -> 0.0010586851 | M40: =I40*G40 -> 0.034487453
A41: Korea | B41: 1875388.2 | C41: Aa2 | D41: 0.0041950485 | E41: =F41+4.23% -> 0.048690645 | F41: 0.0063906452 | G41: 0.264 | H41: Asia | I41: =B41/$B$57 -> 0.053996458 | J41: =I41*D41 -> 0.00022651776 | K41: =I41*E41 -> 0.0026291224 | L41: =I41*F41 -> 0.0003450722 | M41: =I41*G41 -> 0.014255065
A42: Laos | B42: 16502.933 | C42: Caa2 | D42: 0.076509694 | E42: =F42+4.23% -> 0.1588532 | F42: 0.1165532 | G42: 0.2 | H42: Asia | I42: =B42/$B$57 -> 0.00047515492 | J42: =I42*D42 -> 3.6353958e-05 | K42: =I42*E42 -> 7.5479877e-05 | L42: =I42*F42 -> 5.5380824e-05 | M42: =I42*G42 -> 9.5030984e-05
A43: Macao | B43: 49467.259 | C43: Aa3 | D43: 0.0050939875 | E43: =F43+4.23% -> 0.050060069 | F43: 0.0077600691 | G43: 0.25 | H43: Asia | I43: =B43/$B$57 -> 0.0014242687 | J43: =I43*D43 -> 7.255207e-06 | K43: =I43*E43 -> 7.1298991e-05 | L43: =I43*F43 -> 1.1052424e-05 | M43: =I43*G43 -> 0.00035606718
A44: Malaysia | B44: 422227.01 | C44: A3 | D44: 0.010187975 | E44: =F44+4.23% -> 0.057820138 | F44: 0.015520138 | G44: 0.24 | H44: Asia | I44: =B44/$B$57 -> 0.012156823 | J44: =I44*D44 -> 0.00012385341 | K44: =I44*E44 -> 0.0007029092 | L44: =I44*F44 -> 0.00018867558 | M44: =I44*G44 -> 0.0029176376
... A56: Vietnam | B56: 476388.23 | C56: Ba2 | D56: 0.025569819 | E56: =F56+4.23% -> 0.081252504 | F56: 0.038952504 | G56: 0.2 | H56: Asia | I56: =B56/$B$57 -> 0.013716241 | J56: =I56*D56 -> 0.00035072181 | K56: =I56*E56 -> 0.0011144789 | L56: =I56*F56 -> 0.00053428194 | M56: =I56*G56 -> 0.0027432482
A57: Asia | B57: =SUM(B33:B56) -> 34731689 | D57: =SUM(J33:J56) -> 0.0097961467 | E57: =F57+4.23% -> 0.057223236 | F57: =SUM(L33:L56) -> 0.014923236 | G57: =SUM(M33:M56) -> 0.25654535 | I57: =SUM(I33:I56) -> 1
A58: Australia | B58: 1757022.5 | C58: Aaa | D58: 0 | E58: =F58+4.23% -> 0.0423 | F58: 0 | G58: 0.3 | H58: Australia & New Zealand | I58: =B58/$B$61 -> 0.87041254 | J58: =I58*D58 -> 0 | K58: =I58*E58 -> 0.036818451 | L58: =I58*F58 -> 0 | M58: =I58*G58 -> 0.26112376
A59: Cook Islands | B59: 1414 | C59: B1 | D59: 0.038254847 | E59: =F59+4.23% -> 0.1005766 | F59: 0.058276598 | G59: 0.2 | H59: Australia & New Zealand | I59: =B59/$B$61 -> 0.00070048242 | J59: =I59*D59 -> 2.6796848e-05 | K59: =I59*E59 -> 7.0452138e-05 | L59: =I59*F59 -> 4.0821732e-05 | M59: =I59*G59 -> 0.00014009648
A60: New Zealand | B60: 260172.39 | C60: Aaa | D60: 0 | E60: =F60+4.23% -> 0.0423 | F60: 0 | G60: 0.28 | H60: Australia & New Zealand | I60: =B60/$B$61 -> 0.12888697 | J60: =I60*D60 -> 0 | K60: =I60*E60 -> 0.005451919 | L60: =I60*F60 -> 0 | M60: =I60*G60 -> 0.036088353
A61: Australia & New Zealand | B61: =SUM(B58:B60) -> 2018608.8 | D61: =SUM(J58:J60) -> 2.6796848e-05 | E61: =F61+4.23% -> 0.042340822 | F61: =SUM(L58:L60) -> 4.0821732e-05 | G61: =SUM(M58:M60) -> 0.29735221 | I61: =SUM(I58:I60) -> 1
A62: Aruba | B62: 4265.6507 | C62: Baa3 | D62: 0.018677954 | E62: =F62+4.23% -> 0.070753587 | F62: 0.028453587 | G62: 0.22 | H62: Caribbean | I62: =B62/$B$76 -> 0.012264167 | J62: =I62*D62 -> 0.00022906955 | K62: =I62*E62 -> 0.00086773382 | L62: =I62*F62 -> 0.00034895955 | M62: =I62*G62 -> 0.0026981168
A63: Bahamas | B63: 15832.8 | C63: B1 | D63: 0.038254847 | E63: =F63+4.23% -> 0.1005766 | F63: 0.058276598 | G63: 0 | H63: Caribbean | I63: =B63/$B$76 -> 0.045520865 | J63: =I63*D63 -> 0.0017413937 | K63: =I63*E63 -> 0.0045783337 | L63: =I63*F63 -> 0.0026528011 | M63: =I63*G63 -> 0
A64: Barbados | B64: 7498.05 | C64: B2 | D64: 0.046744826 | E64: =F64+4.23% -> 0.11351005 | F64: 0.071210046 | G64: 0.09 | H64: Caribbean | I64: =B64/$B$76 -> 0.021557635 | J64: =I64*D64 -> 0.0010077079 | K64: =I64*E64 -> 0.0024470081 | L64: =I64*F64 -> 0.0015351202 | M64: =I64*G64 -> 0.0019401871
A65: Bermuda | B65: 9233.6 | C65: A2 | D65: 0.0071915117 | E65: =F65+4.23% -> 0.053255392 | F65: 0.010955392 | G65: 0 | H65: Caribbean | I65: =B65/$B$76 -> 0.026547512 | J65: =I65*D65 -> 0.00019091675 | K65: =I65*E65 -> 0.0014137982 | L65: =I65*F65 -> 0.0002908384 | M65: =I65*G65 -> 0
A66: Cayman Islands | B66: 7241.2443 | C66: Aa3 | D66: 0.0050939875 | E66: =F66+4.23% -> 0.050060069 | F66: 0.0077600691 | G66: 0 | H66: Caribbean | I66: =B66/$B$76 -> 0.020819293 | J66: =I66*D66 -> 0.00010605322 | K66: =I66*E66 -> 0.0010422152 | L66: =I66*F66 -> 0.00016155915 | M66: =I66*G66 -> 0
A67: Cuba | B67: 107352 | C67: Ca | D67: 0.10197963 | E67: =F67+4.23% -> 0.19765354 | F67: 0.15535354 | G67: 0.35 | H67: Caribbean | I67: =B67/$B$76 -> 0.30864761 | J67: =I67*D67 -> 0.031475769 | K67: =I67*E67 -> 0.061005293 | L67: =I67*F67 -> 0.047949499 | M67: =I67*G67 -> 0.10802666
A68: Curacao | B68: 3561.1782 | C68: Baa3 | D68: 0.018677954 | E68: =F68+4.23% -> 0.070753587 | F68: 0.028453587 | G68: 0.22 | H68: Caribbean | I68: =B68/$B$76 -> 0.010238739 | J68: =I68*D68 -> 0.0001912387 | K68: =I68*E68 -> 0.00072442752 | L68: =I68*F68 -> 0.00029132885 | M68: =I68*G68 -> 0.0022525226
...

Sheet Regional breakdown
A1: Country | B1: ='Country GDP'!B1 -> GDP (in millions) in 2024 | C1: ='Sovereign Ratings (Moody''s,S&P)'!D1 -> Moody's rating | D1: Sovereign CDS | E1: Adj. Default Spread | F1: Equity Risk Premium | G1: Country Risk Premium | H1: Corporate Tax Rate | I1: Region
A2: ='Sovereign Ratings (Moody''s,S&P)'!A2 -> Abu Dhabi | B2: =VLOOKUP(A2,'Country GDP'!$A$2:$B$181,2,FALSE()) -> 310000 | C2: =VLOOKUP(A2,'Sovereign Ratings (Moody''s,S&P)'!$A$2:$D$158,4,FALSE()) -> Aa2 | D2: =VLOOKUP(A2,'10-year CDS Spreads'!$A$2:$C$158,3,FALSE()) -> 0.006 | E2: =VLOOKUP(A2,'ERPs by country'!$A$9:$F$165,4,FALSE()) -> 0.0041950485 | F2: =VLOOKUP(A2,'ERPs by country'!$A$9:$F$165,5,FALSE()) -> 0.048690645 | G2: =VLOOKUP(A2,'ERPs by country'!$A$9:$F$165,6,FALSE()) -> 0.0063906452 | H2: =VLOOKUP(A2,'Country Tax Rates'!$A$2:$B$159,2,FALSE()) -> 0.09 | I2: =VLOOKUP(A2,'Regional lookup table'!$A$2:$B$162,2,FALSE()) -> Middle East
A3: ='Sovereign Ratings (Moody''s,S&P)'!A3 -> Albania | B3: =VLOOKUP(A3,'Country GDP'!$A$2:$B$181,2,FALSE()) -> 27046.429 | C3: =VLOOKUP(A3,'Sovereign Ratings (Moody''s,S&P)'!$A$2:$D$158,4,FALSE()) -> Ba3 | D3: =VLOOKUP(A3,'10-year CDS Spreads'!$A$2:$C$158,3,FALSE()) -> NA | E3: =VLOOKUP(A3,'ERPs by country'!$A$9:$F$165,4,FALSE()) -> 0.030563925 | F3: =VLOOKUP(A3,'ERPs by country'!$A$9:$F$165,5,FALSE()) -> 0.088860415 | G3: =VLOOKUP(A3,'ERPs by country'!$A$9:$F$165,6,FALSE()) -> 0.046560415 | H3: =VLOOKUP(A3,'Country Tax Rates'!$A$2:$B$159,2,FALSE()) -> 0.15 | I3: =VLOOKUP(A3,'Regional lookup table'!$A$2:$B$162,2,FALSE()) -> Eastern Europe & Russia
A4: ='Sovereign Ratings (Moody''s,S&P)'!A4 -> Andorra (Principality of) | B4: =VLOOKUP(A4,'Country GDP'!$A$2:$B$181,2,FALSE()) -> 4039.8424 | C4: =VLOOKUP(A4,'Sovereign Ratings (Moody''s,S&P)'!$A$2:$D$158,4,FALSE()) -> Baa1 | D4: =VLOOKUP(A4,'10-year CDS Spreads'!$A$2:$C$158,3,FALSE()) -> NA | E4: =VLOOKUP(A4,'ERPs by country'!$A$9:$F$165,4,FALSE()) -> 0.013583967 | F4: =VLOOKUP(A4,'ERPs by country'!$A$9:$F$165,5,FALSE()) -> 0.062993518 | G4: =VLOOKUP(A4,'ERPs by country'!$A$9:$F$165,6,FALSE()) -> 0.020693518 | H4: =VLOOKUP(A4,'Country Tax Rates'!$A$2:$B$159,2,FALSE()) -> 0.1 | I4: =VLOOKUP(A4,'Regional lookup table'!$A$2:$B$162,2,FALSE()) -> Western Europe
A5: ='Sovereign Ratings (Moody''s,S&P)'!A5 -> Angola | B5: =VLOOKUP(A5,'Country GDP'!$A$2:$B$181,2,FALSE()) -> 100998.92 | C5: =VLOOKUP(A5,'Sovereign Ratings (Moody''s,S&P)'!$A$2:$D$158,4,FALSE()) -> B3 | D5: =VLOOKUP(A5,'10-year CDS Spreads'!$A$2:$C$158,3,FALSE()) -> 0.0624 | E5: =VLOOKUP(A5,'ERPs by country'!$A$9:$F$165,4,FALSE()) -> 0.055234805 | F5: =VLOOKUP(A5,'ERPs by country'!$A$9:$F$165,5,FALSE()) -> 0.12644349 | G5: =VLOOKUP(A5,'ERPs by country'!$A$9:$F$165,6,FALSE()) -> 0.084143495 | H5: =VLOOKUP(A5,'Country Tax Rates'!$A$2:$B$159,2,FALSE()) -> 0.25 | I5: =VLOOKUP(A5,'Regional lookup table'!$A$2:$B$162,2,FALSE()) -> Africa
A6: ='Sovereign Ratings (Moody''s,S&P)'!A6 -> Argentina | B6: =VLOOKUP(A6,'Country GDP'!$A$2:$B$181,2,FALSE()) -> 638365.46 | C6: =VLOOKUP(A6,'Sovereign Ratings (Moody''s,S&P)'!$A$2:$D$158,4,FALSE()) -> Caa1 | D6: =VLOOKUP(A6,'10-year CDS Spreads'!$A$2:$C$158,3,FALSE()) -> NA | E6: =VLOOKUP(A6,'ERPs by country'!$A$9:$F$165,4,FALSE()) -> 0.063724785 | F6: =VLOOKUP(A6,'ERPs by country'!$A$9:$F$165,5,FALSE()) -> 0.13937694 | G6: =VLOOKUP(A6,'ERPs by country'!$A$9:$F$165,6,FALSE()) -> 0.097076943 | H6: =VLOOKUP(A6,'Country Tax Rates'!$A$2:$B$159,2,FALSE()) -> 0.35 | I6: =VLOOKUP(A6,'Regional lookup table'!$A$2:$B$162,2,FALSE()) -> Central and South America
A7: ='Sovereign Ratings (Moody''s,S&P)'!A7 -> Armenia | B7: =VLOOKUP(A7,'Country GDP'!$A$2:$B$181,2,FALSE()) -> 25955.275 | C7: =VLOOKUP(A7,'Sovereign Ratings (Moody''s,S&P)'!$A$2:$D$158,4,FALSE()) -> Ba3 | D7: =VLOOKUP(A7,'10-year CDS Spreads'!$A$2:$C$158,3,FALSE()) -> NA | E7: =VLOOKUP(A7,'ERPs by country'!$A$9:$F$165,4,FALSE()) -> 0.030563925 | F7: =VLOOKUP(A7,'ERPs by country'!$A$9:$F$165,5,FALSE()) -> 0.088860415 | G7: =VLOOKUP(A7,'ERPs by country'!$A$9:$F$165,6,FALSE()) -> 0.046560415 | H7: =VLOOKUP(A7,'Country Tax Rates'!$A$2:$B$159,2,FALSE()) -> 0.18 | I7: =VLOOKUP(A7,'Regional lookup table'!$A$2:$B$162,2,FALSE()) -> Eastern Europe & Russia
A8: ='Sovereign Ratings (Moody''s,S&P)'!A8 -> Aruba | B8: =VLOOKUP(A8,'Country GDP'!$A$2:$B$181,2,FALSE()) -> 4265.6507 | C8: =VLOOKUP(A8,'Sovereign Ratings (Moody''s,S&P)'!$A$2:$D$158,4,FALSE()) -> Baa3 | D8: =VLOOKUP(A8,'10-year CDS Spreads'!$A$2:$C$158,3,FALSE()) -> NA | E8: =VLOOKUP(A8,'ERPs by country'!$A$9:$F$165,4,FALSE()) -> 0.018677954 | F8: =VLOOKUP(A8,'ERPs by country'!$A$9:$F$165,5,FALSE()) -> 0.070753587 | G8: =VLOOKUP(A8,'ERPs by country'!$A$9:$F$165,6,FALSE()) -> 0.028453587 | H8: =VLOOKUP(A8,'Country Tax Rates'!$A$2:$B$159,2,FALSE()) -> 0.22 | I8: =VLOOKUP(A8,'Regional lookup table'!$A$2:$B$162,2,FALSE()) -> Caribbean
A9: ='Sovereign Ratings (Moody''s,S&P)'!A9 -> Australia | B9: =VLOOKUP(A9,'Country GDP'!$A$2:$B$181,2,FALSE()) -> 1757022.5 | C9: =VLOOKUP(A9,'Sovereign Ratings (Moody''s,S&P)'!$A$2:$D$158,4,FALSE()) -> Aaa | D9: =VLOOKUP(A9,'10-year CDS Spreads'!$A$2:$C$158,3,FALSE()) -> 0.0019 | E9: =VLOOKUP(A9,'ERPs by country'!$A$9:$F$165,4,FALSE()) -> 0 | F9: =VLOOKUP(A9,'ERPs by country'!$A$9:$F$165,5,FALSE()) -> 0.0423 | G9: =VLOOKUP(A9,'ERPs by country'!$A$9:$F$165,6,FALSE()) -> 0 | H9: =VLOOKUP(A9,'Country Tax Rates'!$A$2:$B$159,2,FALSE()) -> 0.3 | I9: =VLOOKUP(A9,'Regional lookup table'!$A$2:$B$162,2,FALSE()) -> Australia & New Zealand
A10: ='Sovereign Ratings (Moody''s,S&P)'!A10 -> Austria | B10: =VLOOKUP(A10,'Country GDP'!$A$2:$B$181,2,FALSE()) -> 534790.72 | C10: =VLOOKUP(A10,'Sovereign Ratings (Moody''s,S&P)'!$A$2:$D$158,4,FALSE()) -> Aa1 | D10: =VLOOKUP(A10,'10-year CDS Spreads'!$A$2:$C$158,3,FALSE()) -> 0.0028 | E10: =VLOOKUP(A10,'ERPs by country'!$A$9:$F$165,4,FALSE()) -> 0.0023336792 | F10: =VLOOKUP(A10,'ERPs by country'!$A$9:$F$165,5,FALSE()) -> 0.045855076 | G10: =VLOOKUP(A10,'ERPs by country'!$A$9:$F$165,6,FALSE()) -> 0.0035550758 | H10: =VLOOKUP(A10,'Country Tax Rates'!$A$2:$B$159,2,FALSE()) -> 0.23 | I10: =VLOOKUP(A10,'Regional lookup table'!$A$2:$B$162,2,FALSE()) -> Western Europe
A11: ='Sovereign Ratings (Moody''s,S&P)'!A11 -> Azerbaijan | B11: =VLOOKUP(A11,'Country GDP'!$A$2:$B$181,2,FALSE()) -> 74315.882 | C11: =VLOOKUP(A11,'Sovereign Ratings (Moody''s,S&P)'!$A$2:$D$158,4,FALSE()) -> Baa3 | D11: =VLOOKUP(A11,'10-year CDS Spreads'!$A$2:$C$158,3,FALSE()) -> NA | E11: =VLOOKUP(A11,'ERPs by country'!$A$9:$F$165,4,FALSE()) -> 0.018677954 | F11: =VLOOKUP(A11,'ERPs by country'!$A$9:$F$165,5,FALSE()) -> 0.070753587 | G11: =VLOOKUP(A11,'ERPs by country'!$A$9:$F$165,6,FALSE()) -> 0.028453587 | H11: =VLOOKUP(A11,'Country Tax Rates'!$A$2:$B$159,2,FALSE()) -> 0.2 | I11: =VLOOKUP(A11,'Regional lookup table'!$A$2:$B$162,2,FALSE()) -> Eastern Europe & Russia
A12: ='Sovereign Ratings (Moody''s,S&P)'!A12 -> Bahamas | B12: =VLOOKUP(A12,'Country GDP'!$A$2:$B$181,2,FALSE()) -> 15832.8 | C12: =VLOOKUP(A12,'Sovereign Ratings (Moody''s,S&P)'!$A$2:$D$158,4,FALSE()) -> B1 | D12: =VLOOKUP(A12,'10-year CDS Spreads'!$A$2:$C$158,3,FALSE()) -> NA | E12: =VLOOKUP(A12,'ERPs by country'!$A$9:$F$165,4,FALSE()) -> 0.038254847 | F12: =VLOOKUP(A12,'ERPs by country'!$A$9:$F$165,5,FALSE()) -> 0.1005766 | G12: =VLOOKUP(A12,'ERPs by country'!$A$9:$F$165,6,FALSE()) -> 0.058276598 | H12: =VLOOKUP(A12,'Country Tax Rates'!$A$2:$B$159,2,FALSE()) -> 0 | I12: =VLOOKUP(A12,'Regional lookup table'!$A$2:$B$162,2,FALSE()) -> Caribbean
A13: ='Sovereign Ratings (Moody''s,S&P)'!A13 -> Bahrain | B13: =VLOOKUP(A13,'Country GDP'!$A$2:$B$181,2,FALSE()) -> 47109.734 | C13: =VLOOKUP(A13,'Sovereign Ratings (Moody''s,S&P)'!$A$2:$D$158,4,FALSE()) -> B2 | D13: =VLOOKUP(A13,'10-year CDS Spreads'!$A$2:$C$158,3,FALSE()) -> 0.0247 | E13: =VLOOKUP(A13,'ERPs by country'!$A$9:$F$165,4,FALSE()) -> 0.046744826 | F13: =VLOOKUP(A13,'ERPs by country'!$A$9:$F$165,5,FALSE()) -> 0.11351005 | G13: =VLOOKUP(A13,'ERPs by country'!$A$9:$F$165,6,FALSE()) -> 0.071210046 | H13: =VLOOKUP(A13,'Country Tax Rates'!$A$2:$B$159,2,FALSE()) -> 0 | I13: =VLOOKUP(A13,'Regional lookup table'!$A$2:$B$162,2,FALSE()) -> Middle East
... A158: ='Sovereign Ratings (Moody''s,S&P)'!A158 -> Zambia | B158: =VLOOKUP(A158,'Country GDP'!$A$2:$B$181,2,FALSE()) -> 25303.185 | C158: =VLOOKUP(A158,'Sovereign Ratings (Moody''s,S&P)'!$A$2:$D$158,4,FALSE()) -> Caa2 | D158: =VLOOKUP(A158,'10-year CDS Spreads'!$A$2:$C$158,3,FALSE()) -> 0.0408 | E158: =VLOOKUP(A158,'ERPs by country'!$A$9:$F$165,4,FALSE()) -> 0.076509694 | F158: =VLOOKUP(A158,'ERPs by country'!$A$9:$F$165,5,FALSE()) -> 0.1588532 | G158: =VLOOKUP(A158,'ERPs by country'!$A$9:$F$165,6,FALSE()) -> 0.1165532 | H158: =VLOOKUP(A158,'Country Tax Rates'!$A$2:$B$159,2,FALSE()) -> 0.3 | I158: =VLOOKUP(A158,'Regional lookup table'!$A$2:$B$162,2,FALSE()) -> Africa

Sheet Sovereign Ratings (Moody's,S&P)
A1: Country | B1: S&P Rating | C1: Fitch rating | D1: Moody's rating | E1: Moody's Rating (unadj)
A2: ='Ratings worksheet'!A2 -> Abu Dhabi | B2: =VLOOKUP(A2,'Ratings worksheet'!$A$2:$C$159,2,FALSE()) -> #N/A | C2: =VLOOKUP(A2,'Ratings worksheet'!$E$2:$H$159,4,FALSE()) -> #N/A | D2: =IF(E2="NR",VLOOKUP(B2,'Sovereign Ratings (Moody''s,S&P)'!$G$9:$H$34,2,FALSE()),E2) -> Aa2 | E2: =VLOOKUP(A2,'Ratings worksheet'!$A$2:$C$159,3,FALSE()) -> Aa2 | G2: GOVERNMENT BOND RATINGS
A3: ='Ratings worksheet'!A3 -> Albania | B3: =VLOOKUP(A3,'Ratings worksheet'!$A$2:$C$159,2,FALSE()) -> BB | C3: =VLOOKUP(A3,'Ratings worksheet'!$E$2:$H$159,4,FALSE()) -> NR | D3: =IF(E3="NR",VLOOKUP(B3,'Sovereign Ratings (Moody''s,S&P)'!$G$9:$H$34,2,FALSE()),E3) -> Ba3 | E3: =VLOOKUP(A3,'Ratings worksheet'!$A$2:$C$159,3,FALSE()) -> Ba3 | G3: In local currency
A4: ='Ratings worksheet'!A4 -> Andorra (Principality of) | B4: =VLOOKUP(A4,'Ratings worksheet'!$A$2:$C$159,2,FALSE()) -> A- | C4: =VLOOKUP(A4,'Ratings worksheet'!$E$2:$H$159,4,FALSE()) -> #N/A | D4: =IF(E4="NR",VLOOKUP(B4,'Sovereign Ratings (Moody''s,S&P)'!$G$9:$H$34,2,FALSE()),E4) -> Baa1 | E4: =VLOOKUP(A4,'Ratings worksheet'!$A$2:$C$159,3,FALSE()) -> Baa1 | G4: S&P: These are the S&P sovereign local currency ratings
A5: ='Ratings worksheet'!A5 -> Angola | B5: =VLOOKUP(A5,'Ratings worksheet'!$A$2:$C$159,2,FALSE()) -> B- | C5: =VLOOKUP(A5,'Ratings worksheet'!$E$2:$H$159,4,FALSE()) -> B- | D5: =IF(E5="NR",VLOOKUP(B5,'Sovereign Ratings (Moody''s,S&P)'!$G$9:$H$34,2,FALSE()),E5) -> B3 | E5: =VLOOKUP(A5,'Ratings worksheet'!$A$2:$C$159,3,FALSE()) -> B3 | G5: Moody's: These are the Moody's local currency rating
A6: ='Ratings worksheet'!A6 -> Argentina | B6: =VLOOKUP(A6,'Ratings worksheet'!$A$2:$C$159,2,FALSE()) -> CCC+ | C6: =VLOOKUP(A6,'Ratings worksheet'!$E$2:$H$159,4,FALSE()) -> CCC+ | D6: =IF(E6="NR",VLOOKUP(B6,'Sovereign Ratings (Moody''s,S&P)'!$G$9:$H$34,2,FALSE()),E6) -> Caa1 | E6: =VLOOKUP(A6,'Ratings worksheet'!$A$2:$C$159,3,FALSE()) -> Caa1 | G6: In red: These are countries where S&P has a rating and Moody's does not. The following lookup table is used to estimate the
A7: ='Ratings worksheet'!A7 -> Armenia | B7: =VLOOKUP(A7,'Ratings worksheet'!$A$2:$C$159,2,FALSE()) -> BB- | C7: =VLOOKUP(A7,'Ratings worksheet'!$E$2:$H$159,4,FALSE()) -> BB- | D7: =IF(E7="NR",VLOOKUP(B7,'Sovereign Ratings (Moody''s,S&P)'!$G$9:$H$34,2,FALSE()),E7) -> Ba3 | E7: =VLOOKUP(A7,'Ratings worksheet'!$A$2:$C$159,3,FALSE()) -> Ba3 | G7: Moody's equivalent rating for these countries.
A8: ='Ratings worksheet'!A8 -> Aruba | B8: =VLOOKUP(A8,'Ratings worksheet'!$A$2:$C$159,2,FALSE()) -> BBB+ | C8: =VLOOKUP(A8,'Ratings worksheet'!$E$2:$H$159,4,FALSE()) -> BBB- | D8: =IF(E8="NR",VLOOKUP(B8,'Sovereign Ratings (Moody''s,S&P)'!$G$9:$H$34,2,FALSE()),E8) -> Baa3 | E8: =VLOOKUP(A8,'Ratings worksheet'!$A$2:$C$159,3,FALSE()) -> Baa3 | G8: S&P/Fitch | H8: Moody's
A9: ='Ratings worksheet'!A9 -> Australia | B9: =VLOOKUP(A9,'Ratings worksheet'!$A$2:$C$159,2,FALSE()) -> AAA | C9: =VLOOKUP(A9,'Ratings worksheet'!$E$2:$H$159,4,FALSE()) -> AAA | D9: =IF(E9="NR",VLOOKUP(B9,'Sovereign Ratings (Moody''s,S&P)'!$G$9:$H$34,2,FALSE()),E9) -> Aaa | E9: =VLOOKUP(A9,'Ratings worksheet'!$A$2:$C$159,3,FALSE()) -> Aaa | G9: A | H9: A2
A10: ='Ratings worksheet'!A10 -> Austria | B10: =VLOOKUP(A10,'Ratings worksheet'!$A$2:$C$159,2,FALSE()) -> AA+ | C10: =VLOOKUP(A10,'Ratings worksheet'!$E$2:$H$159,4,FALSE()) -> AA | D10: =IF(E10="NR",VLOOKUP(B10,'Sovereign Ratings (Moody''s,S&P)'!$G$9:$H$34,2,FALSE()),E10) -> Aa1 | E10: =VLOOKUP(A10,'Ratings worksheet'!$A$2:$C$159,3,FALSE()) -> Aa1 | G10: A- | H10: A3
A11: ='Ratings worksheet'!A11 -> Azerbaijan | B11: =VLOOKUP(A11,'Ratings worksheet'!$A$2:$C$159,2,FALSE()) -> NR | C11: =VLOOKUP(A11,'Ratings worksheet'!$E$2:$H$159,4,FALSE()) -> BBB- | D11: =IF(E11="NR",VLOOKUP(B11,'Sovereign Ratings (Moody''s,S&P)'!$G$9:$H$34,2,FALSE()),E11) -> Baa3 | E11: =VLOOKUP(A11,'Ratings worksheet'!$A$2:$C$159,3,FALSE()) -> Baa3 | G11: A+ | H11: A1
A12: ='Ratings worksheet'!A12 -> Bahamas | B12: =VLOOKUP(A12,'Ratings worksheet'!$A$2:$C$159,2,FALSE()) -> BB- | C12: =VLOOKUP(A12,'Ratings worksheet'!$E$2:$H$159,4,FALSE()) -> BB- | D12: =IF(E12="NR",VLOOKUP(B12,'Sovereign Ratings (Moody''s,S&P)'!$G$9:$H$34,2,FALSE()),E12) -> B1 | E12: =VLOOKUP(A12,'Ratings worksheet'!$A$2:$C$159,3,FALSE()) -> B1 | G12: AA | H12: Aa2
A13: ='Ratings worksheet'!A13 -> Bahrain | B13: =VLOOKUP(A13,'Ratings worksheet'!$A$2:$C$159,2,FALSE()) -> B | C13: =VLOOKUP(A13,'Ratings worksheet'!$E$2:$H$159,4,FALSE()) -> B+ | D13: =IF(E13="NR",VLOOKUP(B13,'Sovereign Ratings (Moody''s,S&P)'!$G$9:$H$34,2,FALSE()),E13) -> B2 | E13: =VLOOKUP(A13,'Ratings worksheet'!$A$2:$C$159,3,FALSE()) -> B2 | G13: AA- | H13: Aa3
A14: ='Ratings worksheet'!A14 -> Bangladesh | B14: =VLOOKUP(A14,'Ratings worksheet'!$A$2:$C$159,2,FALSE()) -> B+ | C14: =VLOOKUP(A14,'Ratings worksheet'!$E$2:$H$159,4,FALSE()) -> B+ | D14: =IF(E14="NR",VLOOKUP(B14,'Sovereign Ratings (Moody''s,S&P)'!$G$9:$H$34,2,FALSE()),E14) -> B2 | E14: =VLOOKUP(A14,'Ratings worksheet'!$A$2:$C$159,3,FALSE()) -> B2 | G14: AA+ | H14: Aa1
A15: ='Ratings worksheet'!A15 -> Barbados | B15: =VLOOKUP(A15,'Ratings worksheet'!$A$2:$C$159,2,FALSE()) -> B+ | C15: =VLOOKUP(A15,'Ratings worksheet'!$E$2:$H$159,4,FALSE()) -> B+ | D15: =IF(E15="NR",VLOOKUP(B15,'Sovereign Ratings (Moody''s,S&P)'!$G$9:$H$34,2,FALSE()),E15) -> B2 | E15: =VLOOKUP(A15,'Ratings worksheet'!$A$2:$C$159,3,FALSE()) -> B2 | G15: AAA | H15: Aaa
